Workbook

Sheet Start Here
A1: WELCOME — YOUR AGING PARENT FINANCIAL ORGANIZER
A2: A calm, organized system for family caregiving finances: who paid what, who should reimburse whom, recurring bills, important accounts and documents, subscriptions worth reviewing, family decisions, and a simple monthly handoff any sibling can pick up. Pre-loaded with a realistic sample family so you can see it working before you enter your own.
A4: Step 0 — Go to File > Make a Copy to save this to your own Google Drive. Always work from your own copy, never the original.
A6: QUICK NAVIGATION — click a tab name to jump there
A7: → Parent & Family Setup
A8: → Bills & Recurring Payments
A9: → Expenses & Receipts
A10: → Family Contributions
A11: → Accounts & Important Documents
A12: → Subscriptions Review
A13: → Decisions & Handoff Log
A14: → Dashboard
... A31: WHAT THE COLORS MEAN
A32: YELLOW | B32: YOU TYPE HERE.
A33: WHITE | B33: AUTOMATIC — calculated for you. Don't type over these.
A35: ⚠ PRIVACY — DO NOT STORE IN THIS SPREADSHEET:
A36: Passwords, PINs, Social Security numbers, full bank account numbers, login credentials, or highly sensitive identity information. Use last-4-digits, a document location, or a responsible person's name instead. Medical diagnosis details should only be added if you personally choose to and understand the risk.
A38: Google Sheets & Excel compatible — both included. No software to install for the Google Sheets version.
A40: DISCLAIMER: This is an organizational and recordkeeping tool only. It is not legal, tax, accounting, medical, benefits, or fiduciary advice, and does not constitute audit-proof or court-ready evidence. Always consult a qualified professional for legal, tax, or medical questions.

Sheet Parent & Family Setup
A1: PARENT PROFILE
A3: Parent ID | B3: PARENT1
A4: Parent Name | B4: Eleanor Brooks
A5: Household | B5: Eleanor's apartment, Riverside Commons
A6: Primary Financial Contact | B6: Sarah Chen
A7: Notes | B7: Primary residence; moved from house in 2024.
A10: FAMILY / CAREGIVER TABLE
A12: Person ID | B12: Name | C12: Relationship | D12: Role | E12: Email / Contact Note | F12: Active? | G12: Reimbursement Eligible? | H12: Notes
A13: F1 | B13: Sarah Chen | C13: Daughter | D13: Primary Caregiver | E13: sarah.chen@example.com | F13: Active | G13: Yes | H13: Handles most day-to-day bills and appointments.
A14: F2 | B14: Michael Brooks | C14: Son | D14: Contributing Family Member | E14: michael.b@example.com | F14: Active | G14: Yes
A15: F3 | B15: Rachel Brooks | C15: Daughter | D15: Contributing Family Member | E15: rachel.b@example.com | F15: Active | G15: Yes | H15: Long-distance; handles transportation-related costs remotely.
A16: F4 | B16: Parent Account | C16: N/A | D16: Parent's Own Account | F16: Active | G16: No | H16: Represents Eleanor's own checking account -- not a person to be reimbursed.
A17: F5 | B17: Daniel Kim | C17: Family Friend | D17: Family Contact (example role only) | E17: daniel.k@example.com | F17: Active | G17: No | H17: Point of contact only; not a professional endorsement.
A18: F6 | B18: Robert Brooks | C18: Brother-in-law | D18: Occasional Contributor | F18: Inactive | G18: No | H18: Contributed once in the past; no longer active in caregiving coordination.

Sheet Bills & Recurring Payments
A1: BILLS & RECURRING PAYMENTS
A2: One row per recurring bill. The Warning column on the right flags anything needing attention.
A3: Bill ID | B3: Category | C3: Provider | D3: Description | E3: Amount | F3: Frequency | G3: Due Date | H3: AutoPay? | I3: Payment Account | J3: Responsible Person | K3: Active? | L3: Last Reviewed | M3: Document Link | N3: Notes | O3: Warning (auto)
A4: B1 | B4: Housing | C4: Riverside Commons | D4: Monthly apartment rent | E4: 1450 | F4: Monthly | G4: 46295 | H4: Yes | I4: Eleanor Checking ...4821 | J4: Sarah Chen | K4: Yes | L4: 46266 | O4: =IF($A4="","",IF($K4="No","",IF(AND($G4<>"",$G4<TODAY()),"⚠ overdue",IF(AND($G4<>"",$G4>=TODAY(),$G4-TODAY()<=14),"⚠ due soon",IF($J4="","⚠ no responsible person",IF($I4="","⚠ missing payment account",IF(AND($L4<>"",TODAY()-$L4>180),"⚠ not reviewed recently","")))))))
A5: B2 | B5: Utilities | C5: City Power & Light | D5: Electric bill | E5: 96 | F5: Monthly | G5: 46280 | H5: No | I5: Eleanor Checking ...4821 | J5: Sarah Chen | K5: Yes | L5: 46271 | O5: =IF($A5="","",IF($K5="No","",IF(AND($G5<>"",$G5<TODAY()),"⚠ overdue",IF(AND($G5<>"",$G5>=TODAY(),$G5-TODAY()<=14),"⚠ due soon",IF($J5="","⚠ no responsible person",IF($I5="","⚠ missing payment account",IF(AND($L5<>"",TODAY()-$L5>180),"⚠ not reviewed recently","")))))))
A6: B3 | B6: Insurance | C6: MediGuard Supplement | D6: Medicare supplement premium | E6: 210 | F6: Monthly | G6: 46297 | H6: Yes | I6: Eleanor Checking ...4821 | J6: Parent Account | K6: Yes | L6: 46256 | O6: =IF($A6="","",IF($K6="No","",IF(AND($G6<>"",$G6<TODAY()),"⚠ overdue",IF(AND($G6<>"",$G6>=TODAY(),$G6-TODAY()<=14),"⚠ due soon",IF($J6="","⚠ no responsible person",IF($I6="","⚠ missing payment account",IF(AND($L6<>"",TODAY()-$L6>180),"⚠ not reviewed recently","")))))))
A7: B4 | B7: Medical | C7: Lakeside Cardiology | D7: Specialist copay plan | E7: 45 | F7: Monthly | G7: 46304 | H7: No | I7: Eleanor Checking ...4821 | K7: Yes | L7: 46226 | O7: =IF($A7="","",IF($K7="No","",IF(AND($G7<>"",$G7<TODAY()),"⚠ overdue",IF(AND($G7<>"",$G7>=TODAY(),$G7-TODAY()<=14),"⚠ due soon",IF($J7="","⚠ no responsible person",IF($I7="","⚠ missing payment account",IF(AND($L7<>"",TODAY()-$L7>180),"⚠ not reviewed recently","")))))))
A8: B5 | B8: Pharmacy | C8: CarePlus Pharmacy | D8: Prescription auto-refill service fee | E8: 12 | F8: Monthly | G8: 46300 | H8: Yes | J8: Michael Brooks | K8: Yes | L8: 46241 | O8: =IF($A8="","",IF($K8="No","",IF(AND($G8<>"",$G8<TODAY()),"⚠ overdue",IF(AND($G8<>"",$G8>=TODAY(),$G8-TODAY()<=14),"⚠ due soon",IF($J8="","⚠ no responsible person",IF($I8="","⚠ missing payment account",IF(AND($L8<>"",TODAY()-$L8>180),"⚠ not reviewed recently","")))))))
A9: B6 | B9: Care Services | C9: Home Comfort Aides | D9: Home health aide, 2x/week | E9: 640 | F9: Monthly | G9: 46291 | H9: No | I9: Sarah Checking ...1190 | J9: Sarah Chen | K9: Yes | L9: 46276 | O9: =IF($A9="","",IF($K9="No","",IF(AND($G9<>"",$G9<TODAY()),"⚠ overdue",IF(AND($G9<>"",$G9>=TODAY(),$G9-TODAY()<=14),"⚠ due soon",IF($J9="","⚠ no responsible person",IF($I9="","⚠ missing payment account",IF(AND($L9<>"",TODAY()-$L9>180),"⚠ not reviewed recently","")))))))
A10: B7 | B10: Transportation | C10: SeniorRide Co | D10: Scheduled ride service subscription | E10: 39 | F10: Monthly | G10: 46306 | H10: Yes | I10: Rachel Card ...7742 | J10: Rachel Brooks | K10: Yes | L10: 46261 | O10: =IF($A10="","",IF($K10="No","",IF(AND($G10<>"",$G10<TODAY()),"⚠ overdue",IF(AND($G10<>"",$G10>=TODAY(),$G10-TODAY()<=14),"⚠ due soon",IF($J10="","⚠ no responsible person",IF($I10="","⚠ missing payment account",IF(AND($L10<>"",TODAY()-$L10>180),"⚠ not reviewed recently","")))))))
A11: B8 | B11: Subscriptions | C11: StreamFlix | D11: Streaming service | E11: 15.99 | F11: Monthly | G11: 46294 | H11: Yes | I11: Eleanor Checking ...4821 | J11: Sarah Chen | K11: Yes | L11: 46076 | O11: =IF($A11="","",IF($K11="No","",IF(AND($G11<>"",$G11<TODAY()),"⚠ overdue",IF(AND($G11<>"",$G11>=TODAY(),$G11-TODAY()<=14),"⚠ due soon",IF($J11="","⚠ no responsible person",IF($I11="","⚠ missing payment account",IF(AND($L11<>"",TODAY()-$L11>180),"⚠ not reviewed recently","")))))))
A12: B9 | B12: Phone/Internet | C12: ClearLine Telecom | D12: Phone + internet bundle | E12: 78 | F12: Monthly | G12: 46299 | H12: Yes | I12: Eleanor Checking ...4821 | J12: Sarah Chen | K12: Yes | L12: 46246 | O12: =IF($A12="","",IF($K12="No","",IF(AND($G12<>"",$G12<TODAY()),"⚠ overdue",IF(AND($G12<>"",$G12>=TODAY(),$G12-TODAY()<=14),"⚠ due soon",IF($J12="","⚠ no responsible person",IF($I12="","⚠ missing payment account",IF(AND($L12<>"",TODAY()-$L12>180),"⚠ not reviewed recently","")))))))
A13: B10 | B13: Other | C13: Old Landline Co | D13: Discontinued landline (kept for records) | E13: 0 | F13: Monthly | H13: No | K13: No | L13: 45886 | O13: =IF($A13="","",IF($K13="No","",IF(AND($G13<>"",$G13<TODAY()),"⚠ overdue",IF(AND($G13<>"",$G13>=TODAY(),$G13-TODAY()<=14),"⚠ due soon",IF($J13="","⚠ no responsible person",IF($I13="","⚠ missing payment account",IF(AND($L13<>"",TODAY()-$L13>180),"⚠ not reviewed recently","")))))))
O14: =IF($A14="","",IF($K14="No","",IF(AND($G14<>"",$G14<TODAY()),"⚠ overdue",IF(AND($G14<>"",$G14>=TODAY(),$G14-TODAY()<=14),"⚠ due soon",IF($J14="","⚠ no responsible person",IF($I14="","⚠ missing payment account",IF(AND($L14<>"",TODAY()-$L14>180),"⚠ not reviewed recently","")))))))
O15: =IF($A15="","",IF($K15="No","",IF(AND($G15<>"",$G15<TODAY()),"⚠ overdue",IF(AND($G15<>"",$G15>=TODAY(),$G15-TODAY()<=14),"⚠ due soon",IF($J15="","⚠ no responsible person",IF($I15="","⚠ missing payment account",IF(AND($L15<>"",TODAY()-$L15>180),"⚠ not reviewed recently","")))))))
O16: =IF($A16="","",IF($K16="No","",IF(AND($G16<>"",$G16<TODAY()),"⚠ overdue",IF(AND($G16<>"",$G16>=TODAY(),$G16-TODAY()<=14),"⚠ due soon",IF($J16="","⚠ no responsible person",IF($I16="","⚠ missing payment account",IF(AND($L16<>"",TODAY()-$L16>180),"⚠ not reviewed recently","")))))))
O17: =IF($A17="","",IF($K17="No","",IF(AND($G17<>"",$G17<TODAY()),"⚠ overdue",IF(AND($G17<>"",$G17>=TODAY(),$G17-TODAY()<=14),"⚠ due soon",IF($J17="","⚠ no responsible person",IF($I17="","⚠ missing payment account",IF(AND($L17<>"",TODAY()-$L17>180),"⚠ not reviewed recently","")))))))
O18: =IF($A18="","",IF($K18="No","",IF(AND($G18<>"",$G18<TODAY()),"⚠ overdue",IF(AND($G18<>"",$G18>=TODAY(),$G18-TODAY()<=14),"⚠ due soon",IF($J18="","⚠ no responsible person",IF($I18="","⚠ missing payment account",IF(AND($L18<>"",TODAY()-$L18>180),"⚠ not reviewed recently","")))))))
O19: =IF($A19="","",IF($K19="No","",IF(AND($G19<>"",$G19<TODAY()),"⚠ overdue",IF(AND($G19<>"",$G19>=TODAY(),$G19-TODAY()<=14),"⚠ due soon",IF($J19="","⚠ no responsible person",IF($I19="","⚠ missing payment account",IF(AND($L19<>"",TODAY()-$L19>180),"⚠ not reviewed recently","")))))))
O20: =IF($A20="","",IF($K20="No","",IF(AND($G20<>"",$G20<TODAY()),"⚠ overdue",IF(AND($G20<>"",$G20>=TODAY(),$G20-TODAY()<=14),"⚠ due soon",IF($J20="","⚠ no responsible person",IF($I20="","⚠ missing payment account",IF(AND($L20<>"",TODAY()-$L20>180),"⚠ not reviewed recently","")))))))
O21: =IF($A21="","",IF($K21="No","",IF(AND($G21<>"",$G21<TODAY()),"⚠ overdue",IF(AND($G21<>"",$G21>=TODAY(),$G21-TODAY()<=14),"⚠ due soon",IF($J21="","⚠ no responsible person",IF($I21="","⚠ missing payment account",IF(AND($L21<>"",TODAY()-$L21>180),"⚠ not reviewed recently","")))))))
O22: =IF($A22="","",IF($K22="No","",IF(AND($G22<>"",$G22<TODAY()),"⚠ overdue",IF(AND($G22<>"",$G22>=TODAY(),$G22-TODAY()<=14),"⚠ due soon",IF($J22="","⚠ no responsible person",IF($I22="","⚠ missing payment account",IF(AND($L22<>"",TODAY()-$L22>180),"⚠ not reviewed recently","")))))))
O23: =IF($A23="","",IF($K23="No","",IF(AND($G23<>"",$G23<TODAY()),"⚠ overdue",IF(AND($G23<>"",$G23>=TODAY(),$G23-TODAY()<=14),"⚠ due soon",IF($J23="","⚠ no responsible person",IF($I23="","⚠ missing payment account",IF(AND($L23<>"",TODAY()-$L23>180),"⚠ not reviewed recently","")))))))
O24: =IF($A24="","",IF($K24="No","",IF(AND($G24<>"",$G24<TODAY()),"⚠ overdue",IF(AND($G24<>"",$G24>=TODAY(),$G24-TODAY()<=14),"⚠ due soon",IF($J24="","⚠ no responsible person",IF($I24="","⚠ missing payment account",IF(AND($L24<>"",TODAY()-$L24>180),"⚠ not reviewed recently","")))))))
O25: =IF($A25="","",IF($K25="No","",IF(AND($G25<>"",$G25<TODAY()),"⚠ overdue",IF(AND($G25<>"",$G25>=TODAY(),$G25-TODAY()<=14),"⚠ due soon",IF($J25="","⚠ no responsible person",IF($I25="","⚠ missing payment account",IF(AND($L25<>"",TODAY()-$L25>180),"⚠ not reviewed recently","")))))))
... O303: =IF($A303="","",IF($K303="No","",IF(AND($G303<>"",$G303<TODAY()),"⚠ overdue",IF(AND($G303<>"",$G303>=TODAY(),$G303-TODAY()<=14),"⚠ due soon",IF($J303="","⚠ no responsible person",IF($I303="","⚠ missing payment account",IF(AND($L303<>"",TODAY()-$L303>180),"⚠ not reviewed recently","")))))))

Sheet Expenses & Receipts
A1: EXPENSES & RECEIPTS
A2: Log every caregiving expense as it happens. Reimbursement Status, Reimbursed Amount, and Remaining Reimbursement update automatically once you record payments on the Family Contributions tab.
A3: Expense ID | B3: Date | C3: Category | D3: Description | E3: Paid By | F3: Payment Method | G3: Amount | H3: Parent Expense? | I3: Reimbursable? | J3: Receipt Available? | K3: Receipt/Document Link | L3: Reimbursement Status (auto) | M3: Reimbursed Amount (auto) | N3: Remaining Reimbursement (auto) | O3: Notes | P3: Flag as Disputed?
A4: E1 | B4: 46268 | C4: Home Repair | D4: Emergency plumber call, kitchen leak | E4: Sarah Chen | F4: Card | G4: 600 | H4: Yes | I4: Yes | J4: Yes | L4: =IF($A4="","",IF($P4="Yes","Disputed / Review",IF($I4<>"Yes","Not Reimbursable",IF($M4<=0.004,"Pending",IF($N4<=0.004,"Reimbursed","Partially Reimbursed"))))) | M4: =IF($A4="",0,SUMIF('Family Contributions'!$I$4:$I$1003,$A4,'Family Contributions'!$G$4:$G$1003)) | N4: =IF($A4="",0,IF($I4="Yes",IF(ISNUMBER($G4),$G4,0)-$M4,0)) | P4: No
A5: E2 | B5: 46274 | C5: Pharmacy | D5: Prescription not covered by insurance | E5: Sarah Chen | F5: Card | G5: 180 | H5: Yes | I5: Yes | J5: Yes | L5: =IF($A5="","",IF($P5="Yes","Disputed / Review",IF($I5<>"Yes","Not Reimbursable",IF($M5<=0.004,"Pending",IF($N5<=0.004,"Reimbursed","Partially Reimbursed"))))) | M5: =IF($A5="",0,SUMIF('Family Contributions'!$I$4:$I$1003,$A5,'Family Contributions'!$G$4:$G$1003)) | N5: =IF($A5="",0,IF($I5="Yes",IF(ISNUMBER($G5),$G5,0)-$M5,0)) | P5: No
A6: E3 | B6: 46277 | C6: Medical | D6: Specialist copay (Dr. visit) | E6: Rachel Brooks | F6: Card | G6: 50 | H6: Yes | I6: Yes | J6: Yes | L6: =IF($A6="","",IF($P6="Yes","Disputed / Review",IF($I6<>"Yes","Not Reimbursable",IF($M6<=0.004,"Pending",IF($N6<=0.004,"Reimbursed","Partially Reimbursed"))))) | M6: =IF($A6="",0,SUMIF('Family Contributions'!$I$4:$I$1003,$A6,'Family Contributions'!$G$4:$G$1003)) | N6: =IF($A6="",0,IF($I6="Yes",IF(ISNUMBER($G6),$G6,0)-$M6,0)) | P6: No
A7: E4 | B7: 46279 | C7: Care Services | D7: Extra weekend home aide shift | E7: Michael Brooks | F7: Bank Transfer | G7: 160 | H7: Yes | I7: Yes | J7: Yes | L7: =IF($A7="","",IF($P7="Yes","Disputed / Review",IF($I7<>"Yes","Not Reimbursable",IF($M7<=0.004,"Pending",IF($N7<=0.004,"Reimbursed","Partially Reimbursed"))))) | M7: =IF($A7="",0,SUMIF('Family Contributions'!$I$4:$I$1003,$A7,'Family Contributions'!$G$4:$G$1003)) | N7: =IF($A7="",0,IF($I7="Yes",IF(ISNUMBER($G7),$G7,0)-$M7,0)) | P7: Yes
A8: E5 | B8: 46281 | C8: Transportation | D8: One-off rideshare to hospital | E8: Sarah Chen | F8: Card | G8: 34.5 | H8: Yes | I8: Yes | J8: No | L8: =IF($A8="","",IF($P8="Yes","Disputed / Review",IF($I8<>"Yes","Not Reimbursable",IF($M8<=0.004,"Pending",IF($N8<=0.004,"Reimbursed","Partially Reimbursed"))))) | M8: =IF($A8="",0,SUMIF('Family Contributions'!$I$4:$I$1003,$A8,'Family Contributions'!$G$4:$G$1003)) | N8: =IF($A8="",0,IF($I8="Yes",IF(ISNUMBER($G8),$G8,0)-$M8,0)) | P8: No
A9: E6 | B9: 46272 | C9: Groceries | D9: Weekly grocery run, Eleanor's own card | E9: Parent Account | F9: Card | G9: 92 | H9: Yes | I9: No | J9: Yes | L9: =IF($A9="","",IF($P9="Yes","Disputed / Review",IF($I9<>"Yes","Not Reimbursable",IF($M9<=0.004,"Pending",IF($N9<=0.004,"Reimbursed","Partially Reimbursed"))))) | M9: =IF($A9="",0,SUMIF('Family Contributions'!$I$4:$I$1003,$A9,'Family Contributions'!$G$4:$G$1003)) | N9: =IF($A9="",0,IF($I9="Yes",IF(ISNUMBER($G9),$G9,0)-$M9,0)) | P9: No
A10: E7 | B10: 46284 | C10: Medical | D10: Dental copay | E10: Michael Brooks | F10: Card | G10: 40 | H10: Yes | I10: Yes | J10: Yes | L10: =IF($A10="","",IF($P10="Yes","Disputed / Review",IF($I10<>"Yes","Not Reimbursable",IF($M10<=0.004,"Pending",IF($N10<=0.004,"Reimbursed","Partially Reimbursed"))))) | M10: =IF($A10="",0,SUMIF('Family Contributions'!$I$4:$I$1003,$A10,'Family Contributions'!$G$4:$G$1003)) | N10: =IF($A10="",0,IF($I10="Yes",IF(ISNUMBER($G10),$G10,0)-$M10,0)) | P10: No
L11: =IF($A11="","",IF($P11="Yes","Disputed / Review",IF($I11<>"Yes","Not Reimbursable",IF($M11<=0.004,"Pending",IF($N11<=0.004,"Reimbursed","Partially Reimbursed"))))) | M11: =IF($A11="",0,SUMIF('Family Contributions'!$I$4:$I$1003,$A11,'Family Contributions'!$G$4:$G$1003)) | N11: =IF($A11="",0,IF($I11="Yes",IF(ISNUMBER($G11),$G11,0)-$M11,0))
L12: =IF($A12="","",IF($P12="Yes","Disputed / Review",IF($I12<>"Yes","Not Reimbursable",IF($M12<=0.004,"Pending",IF($N12<=0.004,"Reimbursed","Partially Reimbursed"))))) | M12: =IF($A12="",0,SUMIF('Family Contributions'!$I$4:$I$1003,$A12,'Family Contributions'!$G$4:$G$1003)) | N12: =IF($A12="",0,IF($I12="Yes",IF(ISNUMBER($G12),$G12,0)-$M12,0))
L13: =IF($A13="","",IF($P13="Yes","Disputed / Review",IF($I13<>"Yes","Not Reimbursable",IF($M13<=0.004,"Pending",IF($N13<=0.004,"Reimbursed","Partially Reimbursed"))))) | M13: =IF($A13="",0,SUMIF('Family Contributions'!$I$4:$I$1003,$A13,'Family Contributions'!$G$4:$G$1003)) | N13: =IF($A13="",0,IF($I13="Yes",IF(ISNUMBER($G13),$G13,0)-$M13,0))
L14: =IF($A14="","",IF($P14="Yes","Disputed / Review",IF($I14<>"Yes","Not Reimbursable",IF($M14<=0.004,"Pending",IF($N14<=0.004,"Reimbursed","Partially Reimbursed"))))) | M14: =IF($A14="",0,SUMIF('Family Contributions'!$I$4:$I$1003,$A14,'Family Contributions'!$G$4:$G$1003)) | N14: =IF($A14="",0,IF($I14="Yes",IF(ISNUMBER($G14),$G14,0)-$M14,0))
L15: =IF($A15="","",IF($P15="Yes","Disputed / Review",IF($I15<>"Yes","Not Reimbursable",IF($M15<=0.004,"Pending",IF($N15<=0.004,"Reimbursed","Partially Reimbursed"))))) | M15: =IF($A15="",0,SUMIF('Family Contributions'!$I$4:$I$1003,$A15,'Family Contributions'!$G$4:$G$1003)) | N15: =IF($A15="",0,IF($I15="Yes",IF(ISNUMBER($G15),$G15,0)-$M15,0))
L16: =IF($A16="","",IF($P16="Yes","Disputed / Review",IF($I16<>"Yes","Not Reimbursable",IF($M16<=0.004,"Pending",IF($N16<=0.004,"Reimbursed","Partially Reimbursed"))))) | M16: =IF($A16="",0,SUMIF('Family Contributions'!$I$4:$I$1003,$A16,'Family Contributions'!$G$4:$G$1003)) | N16: =IF($A16="",0,IF($I16="Yes",IF(ISNUMBER($G16),$G16,0)-$M16,0))
L17: =IF($A17="","",IF($P17="Yes","Disputed / Review",IF($I17<>"Yes","Not Reimbursable",IF($M17<=0.004,"Pending",IF($N17<=0.004,"Reimbursed","Partially Reimbursed"))))) | M17: =IF($A17="",0,SUMIF('Family Contributions'!$I$4:$I$1003,$A17,'Family Contributions'!$G$4:$G$1003)) | N17: =IF($A17="",0,IF($I17="Yes",IF(ISNUMBER($G17),$G17,0)-$M17,0))
L18: =IF($A18="","",IF($P18="Yes","Disputed / Review",IF($I18<>"Yes","Not Reimbursable",IF($M18<=0.004,"Pending",IF($N18<=0.004,"Reimbursed","Partially Reimbursed"))))) | M18: =IF($A18="",0,SUMIF('Family Contributions'!$I$4:$I$1003,$A18,'Family Contributions'!$G$4:$G$1003)) | N18: =IF($A18="",0,IF($I18="Yes",IF(ISNUMBER($G18),$G18,0)-$M18,0))
L19: =IF($A19="","",IF($P19="Yes","Disputed / Review",IF($I19<>"Yes","Not Reimbursable",IF($M19<=0.004,"Pending",IF($N19<=0.004,"Reimbursed","Partially Reimbursed"))))) | M19: =IF($A19="",0,SUMIF('Family Contributions'!$I$4:$I$1003,$A19,'Family Contributions'!$G$4:$G$1003)) | N19: =IF($A19="",0,IF($I19="Yes",IF(ISNUMBER($G19),$G19,0)-$M19,0))
L20: =IF($A20="","",IF($P20="Yes","Disputed / Review",IF($I20<>"Yes","Not Reimbursable",IF($M20<=0.004,"Pending",IF($N20<=0.004,"Reimbursed","Partially Reimbursed"))))) | M20: =IF($A20="",0,SUMIF('Family Contributions'!$I$4:$I$1003,$A20,'Family Contributions'!$G$4:$G$1003)) | N20: =IF($A20="",0,IF($I20="Yes",IF(ISNUMBER($G20),$G20,0)-$M20,0))
L21: =IF($A21="","",IF($P21="Yes","Disputed / Review",IF($I21<>"Yes","Not Reimbursable",IF($M21<=0.004,"Pending",IF($N21<=0.004,"Reimbursed","Partially Reimbursed"))))) | M21: =IF($A21="",0,SUMIF('Family Contributions'!$I$4:$I$1003,$A21,'Family Contributions'!$G$4:$G$1003)) | N21: =IF($A21="",0,IF($I21="Yes",IF(ISNUMBER($G21),$G21,0)-$M21,0))
L22: =IF($A22="","",IF($P22="Yes","Disputed / Review",IF($I22<>"Yes","Not Reimbursable",IF($M22<=0.004,"Pending",IF($N22<=0.004,"Reimbursed","Partially Reimbursed"))))) | M22: =IF($A22="",0,SUMIF('Family Contributions'!$I$4:$I$1003,$A22,'Family Contributions'!$G$4:$G$1003)) | N22: =IF($A22="",0,IF($I22="Yes",IF(ISNUMBER($G22),$G22,0)-$M22,0))
... L1003: =IF($A1003="","",IF($P1003="Yes","Disputed / Review",IF($I1003<>"Yes","Not Reimbursable",IF($M1003<=0.004,"Pending",IF($N1003<=0.004,"Reimbursed","Partially Reimbursed"))))) | M1003: =IF($A1003="",0,SUMIF('Family Contributions'!$I$4:$I$1003,$A1003,'Family Contributions'!$G$4:$G$1003)) | N1003: =IF($A1003="",0,IF($I1003="Yes",IF(ISNUMBER($G1003),$G1003,0)-$M1003,0))

Sheet Family Contributions
A1: FAMILY CONTRIBUTIONS & COST SHARING
A2: This is where WHO PAID? / WHO OWES? / HOW MUCH? / FOR WHAT? gets answered. One row per reimbursement payment. Leave Related Expense ID blank for an unapplied family-pool contribution not yet tied to a specific expense.
A3: Contribution ID | B3: Date | C3: Contributor | D3: Intended For | E3: Category | F3: Amount | G3: Applied Amount (auto) | H3: Remaining Available (auto) | I3: Related Expense ID | J3: Notes
A4: C1 | B4: 46270 | C4: Parent Account | D4: Sarah Chen | E4: Reimbursement | F4: 300 | G4: =IF($A4="",0,IF($I4="",0,$F4)) | H4: =IF($A4="","",$F4-$G4) | I4: E1
A5: C2 | B5: 46271 | C5: Michael Brooks | D5: Sarah Chen | E5: Reimbursement | F5: 100 | G5: =IF($A5="",0,IF($I5="",0,$F5)) | H5: =IF($A5="","",$F5-$G5) | I5: E1
A6: C3 | B6: 46272 | C6: Rachel Brooks | D6: Sarah Chen | E6: Reimbursement | F6: 150 | G6: =IF($A6="",0,IF($I6="",0,$F6)) | H6: =IF($A6="","",$F6-$G6) | I6: E1
A7: C4 | B7: 46276 | C7: Michael Brooks | D7: Sarah Chen | E7: Reimbursement | F7: 90 | G7: =IF($A7="",0,IF($I7="",0,$F7)) | H7: =IF($A7="","",$F7-$G7) | I7: E2
A8: C5 | B8: 46278 | C8: Parent Account | D8: Sarah Chen | E8: Reimbursement | F8: 50 | G8: =IF($A8="",0,IF($I8="",0,$F8)) | H8: =IF($A8="","",$F8-$G8) | I8: E2
A9: C6 | B9: 46280 | C9: Parent Account | D9: Rachel Brooks | E9: Reimbursement | F9: 60 | G9: =IF($A9="",0,IF($I9="",0,$F9)) | H9: =IF($A9="","",$F9-$G9) | I9: E3
G10: =IF($A10="",0,IF($I10="",0,$F10)) | H10: =IF($A10="","",$F10-$G10)
A11: C8 | B11: 46246 | C11: Robert Brooks | D11: Sarah Chen | E11: One-time gift toward parent costs | F11: 75 | G11: =IF($A11="",0,IF($I11="",0,$F11)) | H11: =IF($A11="","",$F11-$G11)
G12: =IF($A12="",0,IF($I12="",0,$F12)) | H12: =IF($A12="","",$F12-$G12)
G13: =IF($A13="",0,IF($I13="",0,$F13)) | H13: =IF($A13="","",$F13-$G13)
G14: =IF($A14="",0,IF($I14="",0,$F14)) | H14: =IF($A14="","",$F14-$G14)
G15: =IF($A15="",0,IF($I15="",0,$F15)) | H15: =IF($A15="","",$F15-$G15)
G16: =IF($A16="",0,IF($I16="",0,$F16)) | H16: =IF($A16="","",$F16-$G16)
G17: =IF($A17="",0,IF($I17="",0,$F17)) | H17: =IF($A17="","",$F17-$G17)
G18: =IF($A18="",0,IF($I18="",0,$F18)) | H18: =IF($A18="","",$F18-$G18)
G19: =IF($A19="",0,IF($I19="",0,$F19)) | H19: =IF($A19="","",$F19-$G19)
G20: =IF($A20="",0,IF($I20="",0,$F20)) | H20: =IF($A20="","",$F20-$G20)
G21: =IF($A21="",0,IF($I21="",0,$F21)) | H21: =IF($A21="","",$F21-$G21)
G22: =IF($A22="",0,IF($I22="",0,$F22)) | H22: =IF($A22="","",$F22-$G22)
G23: =IF($A23="",0,IF($I23="",0,$F23)) | H23: =IF($A23="","",$F23-$G23)
... G1003: =IF($A1003="",0,IF($I1003="",0,$F1003)) | H1003: =IF($A1003="","",$F1003-$G1003)

Sheet Accounts & Important Documents
A1: ACCOUNTS & IMPORTANT DOCUMENTS
A2: This is a MAP, not a password vault. ⚠ Do not store passwords or highly sensitive personal credentials in this spreadsheet -- use last-4-digits, a document location, or a responsible person's name instead.
A3: Item ID | B3: Type | C3: Institution / Provider | D3: Account / Document Name | E3: Last 4 (only) | F3: Owner | G3: Authorized Contact | H3: Location / Storage | I3: Document Link | J3: Renewal / Review Date | K3: Responsible Person | L3: Status | M3: Notes | N3: Warning (auto)
A4: D1 | B4: Bank | C4: Riverside Community Bank | D4: Eleanor Checking | E4: 4821 | F4: Eleanor Brooks | G4: Sarah Chen | H4: Home filing cabinet, top drawer | J4: 46376 | K4: Sarah Chen | L4: Active | N4: =IF($A4="","",IF(AND($J4<>"",TODAY()-$J4>365),"⚠ review overdue",""))
A5: D2 | B5: Credit Card | C5: Meridian Visa | D5: Eleanor's everyday card | E5: 2290 | F5: Eleanor Brooks | G5: Sarah Chen | H5: Eleanor's wallet | J5: 46486 | K5: Sarah Chen | L5: Active | N5: =IF($A5="","",IF(AND($J5<>"",TODAY()-$J5>365),"⚠ review overdue",""))
A6: D3 | B6: Insurance | C6: MediGuard | D6: Medicare supplement policy | F6: Eleanor Brooks | G6: Sarah Chen | H6: Home filing cabinet, insurance folder | J6: 45886 | K6: Parent Account | L6: Active | N6: =IF($A6="","",IF(AND($J6<>"",TODAY()-$J6>365),"⚠ review overdue",""))
A7: D4 | B7: Pension/Retirement | C7: State Teachers Pension | D7: Monthly pension | F7: Eleanor Brooks | G7: Sarah Chen | H7: Direct deposit -- no physical document | J7: 46586 | K7: Sarah Chen | L7: Active | N7: =IF($A7="","",IF(AND($J7<>"",TODAY()-$J7>365),"⚠ review overdue",""))
A8: D5 | B8: Property | C8: County Records Office | D8: Prior home sale deed (2024) | F8: Eleanor Brooks | G8: Sarah Chen | H8: Safe deposit box, First National Bank | J8: 46886 | K8: Sarah Chen | L8: Active | N8: =IF($A8="","",IF(AND($J8<>"",TODAY()-$J8>365),"⚠ review overdue",""))
A9: D6 | B9: Legal Document | C9: Family Attorney (example only) | D9: Power of Attorney document (location only) | F9: Eleanor Brooks | G9: Sarah Chen | H9: Attorney's office + copy in home safe | J9: 46536 | K9: Sarah Chen | L9: Active | N9: =IF($A9="","",IF(AND($J9<>"",TODAY()-$J9>365),"⚠ review overdue",""))
A10: D7 | B10: Utilities | C10: ClearLine Telecom | D10: Phone/internet account | F10: Eleanor Brooks | G10: Sarah Chen | H10: Online account -- see Bills tab | J10: 46406 | K10: Sarah Chen | L10: Active | N10: =IF($A10="","",IF(AND($J10<>"",TODAY()-$J10>365),"⚠ review overdue",""))
A11: D8 | B11: ID Document | C11: State DMV | D11: Driver's license / State ID | F11: Eleanor Brooks | G11: Sarah Chen | H11: Eleanor's wallet | J11: 46466 | K11: Sarah Chen | L11: Active | N11: =IF($A11="","",IF(AND($J11<>"",TODAY()-$J11>365),"⚠ review overdue",""))
N12: =IF($A12="","",IF(AND($J12<>"",TODAY()-$J12>365),"⚠ review overdue",""))
N13: =IF($A13="","",IF(AND($J13<>"",TODAY()-$J13>365),"⚠ review overdue",""))
N14: =IF($A14="","",IF(AND($J14<>"",TODAY()-$J14>365),"⚠ review overdue",""))
N15: =IF($A15="","",IF(AND($J15<>"",TODAY()-$J15>365),"⚠ review overdue",""))
N16: =IF($A16="","",IF(AND($J16<>"",TODAY()-$J16>365),"⚠ review overdue",""))
N17: =IF($A17="","",IF(AND($J17<>"",TODAY()-$J17>365),"⚠ review overdue",""))
N18: =IF($A18="","",IF(AND($J18<>"",TODAY()-$J18>365),"⚠ review overdue",""))
N19: =IF($A19="","",IF(AND($J19<>"",TODAY()-$J19>365),"⚠ review overdue",""))
N20: =IF($A20="","",IF(AND($J20<>"",TODAY()-$J20>365),"⚠ review overdue",""))
N21: =IF($A21="","",IF(AND($J21<>"",TODAY()-$J21>365),"⚠ review overdue",""))
N22: =IF($A22="","",IF(AND($J22<>"",TODAY()-$J22>365),"⚠ review overdue",""))
N23: =IF($A23="","",IF(AND($J23<>"",TODAY()-$J23>365),"⚠ review overdue",""))
... N303: =IF($A303="","",IF(AND($J303<>"",TODAY()-$J303>365),"⚠ review overdue",""))

Sheet Subscriptions Review
A1: SUBSCRIPTIONS & MONEY LEAK REVIEW
A3: Provider | B3: Category | C3: Amount | D3: Frequency | E3: Monthly Equivalent (auto) | F3: Used? | G3: Needed? | H3: Cancel Candidate? | I3: Responsible Person | J3: Last Reviewed | K3: Action | L3: Notes
A4: StreamFlix | B4: Entertainment | C4: 15.99 | D4: Monthly | E4: =IF($A4="",0,IF($D4="Monthly",$C4,IF($D4="Annual",$C4/12,IF($D4="Weekly",$C4*52/12,IF($D4="Quarterly",$C4/3,$C4))))) | F4: Unsure | G4: Review | H4: Yes | I4: Sarah Chen | J4: 46076 | K4: Review with Eleanor next visit
A5: Hometown Gazette | B5: News | C5: 60 | D5: Annual | E5: =IF($A5="",0,IF($D5="Monthly",$C5,IF($D5="Annual",$C5/12,IF($D5="Weekly",$C5*52/12,IF($D5="Quarterly",$C5/3,$C5))))) | F5: No | G5: No | H5: Yes | I5: Parent Account | J5: 45906 | K5: Cancel
A6: FitLife Gym | B6: Wellness | C6: 45 | D6: Monthly | E6: =IF($A6="",0,IF($D6="Monthly",$C6,IF($D6="Annual",$C6/12,IF($D6="Weekly",$C6*52/12,IF($D6="Quarterly",$C6/3,$C6))))) | F6: No | G6: No | H6: Yes | I6: Sarah Chen | J6: 46096 | K6: Cancel -- unused since move
A7: SafeCloud Backup | B7: Document Storage | C7: 8.99 | D7: Monthly | E7: =IF($A7="",0,IF($D7="Monthly",$C7,IF($D7="Annual",$C7/12,IF($D7="Weekly",$C7*52/12,IF($D7="Quarterly",$C7/3,$C7))))) | F7: Yes | G7: Yes | H7: No | I7: Sarah Chen | J7: 46266 | K7: Keep
A8: Weekly Herald | B8: News | C8: 12 | D8: Monthly | E8: =IF($A8="",0,IF($D8="Monthly",$C8,IF($D8="Annual",$C8/12,IF($D8="Weekly",$C8*52/12,IF($D8="Quarterly",$C8/3,$C8))))) | F8: Unsure | G8: Review | H8: No | I8: Rachel Brooks | J8: 46191 | K8: Ask Eleanor if still reading it
A9: MedAlert Monitoring | B9: Medical Alert | C9: 34.99 | D9: Monthly | E9: =IF($A9="",0,IF($D9="Monthly",$C9,IF($D9="Annual",$C9/12,IF($D9="Weekly",$C9*52/12,IF($D9="Quarterly",$C9/3,$C9))))) | F9: Yes | G9: Yes | H9: No | I9: Sarah Chen | J9: 46271 | K9: Keep -- actively used
E10: =IF($A10="",0,IF($D10="Monthly",$C10,IF($D10="Annual",$C10/12,IF($D10="Weekly",$C10*52/12,IF($D10="Quarterly",$C10/3,$C10)))))
E11: =IF($A11="",0,IF($D11="Monthly",$C11,IF($D11="Annual",$C11/12,IF($D11="Weekly",$C11*52/12,IF($D11="Quarterly",$C11/3,$C11)))))
E12: =IF($A12="",0,IF($D12="Monthly",$C12,IF($D12="Annual",$C12/12,IF($D12="Weekly",$C12*52/12,IF($D12="Quarterly",$C12/3,$C12)))))
E13: =IF($A13="",0,IF($D13="Monthly",$C13,IF($D13="Annual",$C13/12,IF($D13="Weekly",$C13*52/12,IF($D13="Quarterly",$C13/3,$C13)))))
E14: =IF($A14="",0,IF($D14="Monthly",$C14,IF($D14="Annual",$C14/12,IF($D14="Weekly",$C14*52/12,IF($D14="Quarterly",$C14/3,$C14)))))
E15: =IF($A15="",0,IF($D15="Monthly",$C15,IF($D15="Annual",$C15/12,IF($D15="Weekly",$C15*52/12,IF($D15="Quarterly",$C15/3,$C15)))))
E16: =IF($A16="",0,IF($D16="Monthly",$C16,IF($D16="Annual",$C16/12,IF($D16="Weekly",$C16*52/12,IF($D16="Quarterly",$C16/3,$C16)))))
E17: =IF($A17="",0,IF($D17="Monthly",$C17,IF($D17="Annual",$C17/12,IF($D17="Weekly",$C17*52/12,IF($D17="Quarterly",$C17/3,$C17)))))
E18: =IF($A18="",0,IF($D18="Monthly",$C18,IF($D18="Annual",$C18/12,IF($D18="Weekly",$C18*52/12,IF($D18="Quarterly",$C18/3,$C18)))))
E19: =IF($A19="",0,IF($D19="Monthly",$C19,IF($D19="Annual",$C19/12,IF($D19="Weekly",$C19*52/12,IF($D19="Quarterly",$C19/3,$C19)))))
E20: =IF($A20="",0,IF($D20="Monthly",$C20,IF($D20="Annual",$C20/12,IF($D20="Weekly",$C20*52/12,IF($D20="Quarterly",$C20/3,$C20)))))
E21: =IF($A21="",0,IF($D21="Monthly",$C21,IF($D21="Annual",$C21/12,IF($D21="Weekly",$C21*52/12,IF($D21="Quarterly",$C21/3,$C21)))))
... E303: =IF($A303="",0,IF($D303="Monthly",$C303,IF($D303="Annual",$C303/12,IF($D303="Weekly",$C303*52/12,IF($D303="Quarterly",$C303/3,$C303)))))
A305: Potential Monthly Savings (Cancel Candidates) | E305: =SUMPRODUCT(($H$4:$H$303="Yes")*$E$4:$E$303)
A306: This does not guarantee savings -- confirm cancellation terms before acting.

Sheet Decisions & Handoff Log
A1: DECISIONS & HANDOFF LOG
A2: This is family recordkeeping for continuity, not legal evidence.
A3: Date | B3: Decision / Issue | C3: Category | D3: People Involved | E3: Decision Made | F3: Who Is Responsible | G3: Follow-up Date | H3: Status | I3: Related Expense/Bill | J3: Supporting Document Link | K3: Notes | L3: Warning (auto)
A4: 46266 | B4: Who covers the plumber bill | C4: Reimbursement | D4: Sarah, Michael, Rachel | E4: Split 300/150/150 (Parent/Michael/Rachel) | F4: Michael Brooks | G4: 46281 | H4: Waiting | I4: E1 | L4: =IF($A4="","",IF(AND($G4<>"",$G4<TODAY(),$H4<>"Completed"),"⚠ follow-up overdue",""))
A5: 46277 | B5: Extra aide shift questioned | C5: Care Services | D5: Sarah, Michael | E5: Pending review of receipt | F5: Sarah Chen | G5: 46289 | H5: Review Needed | I5: E4 | L5: =IF($A5="","",IF(AND($G5<>"",$G5<TODAY(),$H5<>"Completed"),"⚠ follow-up overdue",""))
A6: 46226 | B6: Cancel unused gym membership | C6: Subscriptions | D6: Sarah, Eleanor | E6: Agreed to cancel | F6: Sarah Chen | G6: 46246 | H6: Open | L6: =IF($A6="","",IF(AND($G6<>"",$G6<TODAY(),$H6<>"Completed"),"⚠ follow-up overdue",""))
A7: 46191 | B7: Review StreamFlix usage | C7: Subscriptions | D7: Sarah | E7: Not yet reviewed | F7: Sarah Chen | G7: 46256 | H7: Open | L7: =IF($A7="","",IF(AND($G7<>"",$G7<TODAY(),$H7<>"Completed"),"⚠ follow-up overdue",""))
A8: 46256 | B8: Confirm POA document location | C8: Documents | D8: Sarah, Family Attorney | E8: Confirmed at attorney's office + home safe copy | F8: Sarah Chen | H8: Completed | L8: =IF($A8="","",IF(AND($G8<>"",$G8<TODAY(),$H8<>"Completed"),"⚠ follow-up overdue",""))
A9: 46284 | B9: Confirm dental copay reimbursement | C9: Reimbursement | D9: Michael, Parent Account | E9: Reimbursed same day | F9: Michael Brooks | H9: Completed | I9: E7 | L9: =IF($A9="","",IF(AND($G9<>"",$G9<TODAY(),$H9<>"Completed"),"⚠ follow-up overdue",""))
L10: =IF($A10="","",IF(AND($G10<>"",$G10<TODAY(),$H10<>"Completed"),"⚠ follow-up overdue",""))
L11: =IF($A11="","",IF(AND($G11<>"",$G11<TODAY(),$H11<>"Completed"),"⚠ follow-up overdue",""))
L12: =IF($A12="","",IF(AND($G12<>"",$G12<TODAY(),$H12<>"Completed"),"⚠ follow-up overdue",""))
L13: =IF($A13="","",IF(AND($G13<>"",$G13<TODAY(),$H13<>"Completed"),"⚠ follow-up overdue",""))
L14: =IF($A14="","",IF(AND($G14<>"",$G14<TODAY(),$H14<>"Completed"),"⚠ follow-up overdue",""))
L15: =IF($A15="","",IF(AND($G15<>"",$G15<TODAY(),$H15<>"Completed"),"⚠ follow-up overdue",""))
L16: =IF($A16="","",IF(AND($G16<>"",$G16<TODAY(),$H16<>"Completed"),"⚠ follow-up overdue",""))
L17: =IF($A17="","",IF(AND($G17<>"",$G17<TODAY(),$H17<>"Completed"),"⚠ follow-up overdue",""))
L18: =IF($A18="","",IF(AND($G18<>"",$G18<TODAY(),$H18<>"Completed"),"⚠ follow-up overdue",""))
L19: =IF($A19="","",IF(AND($G19<>"",$G19<TODAY(),$H19<>"Completed"),"⚠ follow-up overdue",""))
L20: =IF($A20="","",IF(AND($G20<>"",$G20<TODAY(),$H20<>"Completed"),"⚠ follow-up overdue",""))
L21: =IF($A21="","",IF(AND($G21<>"",$G21<TODAY(),$H21<>"Completed"),"⚠ follow-up overdue",""))
... L303: =IF($A303="","",IF(AND($G303<>"",$G303<TODAY(),$H303<>"Completed"),"⚠ follow-up overdue",""))

Sheet Monthly Family Handoff
A1: MONTHLY FAMILY HANDOFF
A2: Printable monthly summary -- another sibling can take over without a long explanation.
A4: Bills Due Next 30 Days (count) | B4: =SUMPRODUCT(('Bills & Recurring Payments'!$K$4:$K$303="Yes")*('Bills & Recurring Payments'!$G$4:$G$303<>"")*('Bills & Recurring Payments'!$G$4:$G$303>=TODAY())*('Bills & Recurring Payments'!$G$4:$G$303-TODAY()<=30))
A5: Outstanding Reimbursements ($) | B5: =SUMPRODUCT((('Expenses & Receipts'!$L$4:$L$1003="Pending")+('Expenses & Receipts'!$L$4:$L$1003="Partially Reimbursed"))*'Expenses & Receipts'!$N$4:$N$1003)
A6: Expenses This Month ($) | B6: =SUMIFS('Expenses & Receipts'!$G$4:$G$1003,'Expenses & Receipts'!$B$4:$B$1003,">="&DATE(YEAR(TODAY()),MONTH(TODAY()),1),'Expenses & Receipts'!$B$4:$B$1003,"<"&EDATE(DATE(YEAR(TODAY()),MONTH(TODAY()),1),1))
A7: Family Contributions This Month ($) | B7: =SUMPRODUCT((TEXT('Family Contributions'!$B$4:$B$1003,"yyyy-mm")=TEXT(TODAY(),"yyyy-mm"))*'Family Contributions'!$G$4:$G$1003)
A8: Subscriptions/Items Needing Review (count) | B8: =COUNTIF('Subscriptions Review'!$H$4:$H$303,"Yes")+COUNTIF('Accounts & Important Documents'!$N$4:$N$303,"⚠ review overdue")
A9: Open Decisions (count) | B9: =COUNTIF('Decisions & Handoff Log'!$H$4:$H$303,"Open")+COUNTIF('Decisions & Handoff Log'!$H$4:$H$303,"Waiting")+COUNTIF('Decisions & Handoff Log'!$H$4:$H$303,"Review Needed")
A10: Documents/Accounts Needing Update (count) | B10: =COUNTIF('Accounts & Important Documents'!$N$4:$N$303,"⚠ review overdue")
A13: THIS MONTH'S OPEN ITEMS (from Decisions & Handoff Log)
A14: Decision / Issue | B14: Who Is Responsible | C14: Status
A15: ='Decisions & Handoff Log'!B4 | B15: ='Decisions & Handoff Log'!F4 | C15: ='Decisions & Handoff Log'!H4
A16: ='Decisions & Handoff Log'!B5 | B16: ='Decisions & Handoff Log'!F5 | C16: ='Decisions & Handoff Log'!H5
A17: ='Decisions & Handoff Log'!B6 | B17: ='Decisions & Handoff Log'!F6 | C17: ='Decisions & Handoff Log'!H6
A18: ='Decisions & Handoff Log'!B7 | B18: ='Decisions & Handoff Log'!F7 | C18: ='Decisions & Handoff Log'!H7
A19: ='Decisions & Handoff Log'!B8 | B19: ='Decisions & Handoff Log'!F8 | C19: ='Decisions & Handoff Log'!H8
A20: ='Decisions & Handoff Log'!B9 | B20: ='Decisions & Handoff Log'!F9 | C20: ='Decisions & Handoff Log'!H9
A22: For full detail on every expense, bill, and decision, see the individual tabs above.

Sheet Dashboard
A1: FAMILY FINANCIAL DASHBOARD
A3: Monthly Bills ($, Active + Monthly frequency) | B3: =SUMPRODUCT(('Bills & Recurring Payments'!$K$4:$K$303="Yes")*('Bills & Recurring Payments'!$F$4:$F$303="Monthly")*'Bills & Recurring Payments'!$E$4:$E$303)
A4: Expenses YTD ($) | B4: =SUM('Expenses & Receipts'!$G$4:$G$1003)
A5: Reimbursements Pending (count) | B5: =COUNTIF('Expenses & Receipts'!$L$4:$L$1003,"Pending")+COUNTIF('Expenses & Receipts'!$L$4:$L$1003,"Partially Reimbursed")
A6: Family Contributions ($, total applied) | B6: =SUM('Family Contributions'!$G$4:$G$1003)
A7: Outstanding Reimbursement ($) | B7: =SUMPRODUCT((('Expenses & Receipts'!$L$4:$L$1003="Pending")+('Expenses & Receipts'!$L$4:$L$1003="Partially Reimbursed"))*'Expenses & Receipts'!$N$4:$N$1003)
A8: Active Recurring Payments (count) | B8: =COUNTIF('Bills & Recurring Payments'!$K$4:$K$303,"Yes")
A9: Review/Cancellation Candidates (count) | B9: =COUNTIF('Subscriptions Review'!$H$4:$H$303,"Yes")
A10: Open Financial Tasks (count) | B10: =COUNTIF('Decisions & Handoff Log'!$H$4:$H$303,"Open")+COUNTIF('Decisions & Handoff Log'!$H$4:$H$303,"Waiting")+COUNTIF('Decisions & Handoff Log'!$H$4:$H$303,"Review Needed")
A12: NEEDS ATTENTION
A13: Overdue Bills (count) | B13: =COUNTIF('Bills & Recurring Payments'!$O$4:$O$303,"⚠ overdue")
A14: Pending Reimbursements (count) | B14: =B5
A15: Disputed/Review Expenses (count) | B15: =COUNTIF('Expenses & Receipts'!$L$4:$L$1003,"Disputed / Review")
A16: Recurring Charges Needing Review (count) | B16: =B9
A17: Open Decisions/Tasks (count) | B17: =B10
A18: Stale Document/Account Records (count) | B18: =COUNTIF('Accounts & Important Documents'!$N$4:$N$303,"⚠ review overdue")
A90: CHART DATA (auto-calculated from the sheets above — do not edit)
A92: Month | B92: Expenses
A93: 46266 | B93: =SUMIFS('Expenses & Receipts'!$G$4:$G$1003,'Expenses & Receipts'!$B$4:$B$1003,">="&DATE(2026,9,1),'Expenses & Receipts'!$B$4:$B$1003,"<"&DATE(2026,10,1))
A96: Category | B96: Amount
A97: Home Repair | B97: =SUMIF('Expenses & Receipts'!$C$4:$C$1003,"Home Repair",'Expenses & Receipts'!$G$4:$G$1003)
A98: Pharmacy | B98: =SUMIF('Expenses & Receipts'!$C$4:$C$1003,"Pharmacy",'Expenses & Receipts'!$G$4:$G$1003)
A99: Medical | B99: =SUMIF('Expenses & Receipts'!$C$4:$C$1003,"Medical",'Expenses & Receipts'!$G$4:$G$1003)
A100: Care Services | B100: =SUMIF('Expenses & Receipts'!$C$4:$C$1003,"Care Services",'Expenses & Receipts'!$G$4:$G$1003)
A101: Transportation | B101: =SUMIF('Expenses & Receipts'!$C$4:$C$1003,"Transportation",'Expenses & Receipts'!$G$4:$G$1003)
A102: Groceries | B102: =SUMIF('Expenses & Receipts'!$C$4:$C$1003,"Groceries",'Expenses & Receipts'!$G$4:$G$1003)
A103: Utilities | B103: =SUMIF('Expenses & Receipts'!$C$4:$C$1003,"Utilities",'Expenses & Receipts'!$G$4:$G$1003)
A104: Insurance | B104: =SUMIF('Expenses & Receipts'!$C$4:$C$1003,"Insurance",'Expenses & Receipts'!$G$4:$G$1003)
A105: Other | B105: =SUMIF('Expenses & Receipts'!$C$4:$C$1003,"Other",'Expenses & Receipts'!$G$4:$G$1003)
A108: Family Member | B108: Total Paid
A109: Sarah Chen | B109: =SUMIF('Expenses & Receipts'!$E$4:$E$1003,"Sarah Chen",'Expenses & Receipts'!$G$4:$G$1003)
A110: Michael Brooks | B110: =SUMIF('Expenses & Receipts'!$E$4:$E$1003,"Michael Brooks",'Expenses & Receipts'!$G$4:$G$1003)
A111: Rachel Brooks | B111: =SUMIF('Expenses & Receipts'!$E$4:$E$1003,"Rachel Brooks",'Expenses & Receipts'!$G$4:$G$1003)
A112: Parent Account | B112: =SUMIF('Expenses & Receipts'!$E$4:$E$1003,"Parent Account",'Expenses & Receipts'!$G$4:$G$1003)
A113: Daniel Kim | B113: =SUMIF('Expenses & Receipts'!$E$4:$E$1003,"Daniel Kim",'Expenses & Receipts'!$G$4:$G$1003)
A114: Robert Brooks | B114: =SUMIF('Expenses & Receipts'!$E$4:$E$1003,"Robert Brooks",'Expenses & Receipts'!$G$4:$G$1003)
A117: Status | B117: Count
A118: Not Reimbursable | B118: =COUNTIF('Expenses & Receipts'!$L$4:$L$1003,"Not Reimbursable")
A119: Pending | B119: =COUNTIF('Expenses & Receipts'!$L$4:$L$1003,"Pending")
A120: Partially Reimbursed | B120: =COUNTIF('Expenses & Receipts'!$L$4:$L$1003,"Partially Reimbursed")
...
